Workbook

Sheet Schedule
A1: Legacy Real Estate System — Delivery Schedule and Gantt
A2: Project kickoff date | B2: 46328 | C2: Edit the yellow kickoff cell, the blue offset/length columns and the Status column. Everything else is calculated.
A3: Gantt colours: red = critical path · grey = external lead time · black = milestone · other colours = phase. Durations are estimates for the developer to confirm in Phase 0.
N5: =TEXT(N6,"mmm yy") -> Nov 26 | O5: =IF(MONTH(O6)<>MONTH(N6),TEXT(O6,"mmm yy"),"") | P5: =IF(MONTH(P6)<>MONTH(O6),TEXT(P6,"mmm yy"),"") | Q5: =IF(MONTH(Q6)<>MONTH(P6),TEXT(Q6,"mmm yy"),"") | R5: =IF(MONTH(R6)<>MONTH(Q6),TEXT(R6,"mmm yy"),"") | S5: =IF(MONTH(S6)<>MONTH(R6),TEXT(S6,"mmm yy"),"") -> Dec 26 | T5: =IF(MONTH(T6)<>MONTH(S6),TEXT(T6,"mmm yy"),"") | U5: =IF(MONTH(U6)<>MONTH(T6),TEXT(U6,"mmm yy"),"") | V5: =IF(MONTH(V6)<>MONTH(U6),TEXT(V6,"mmm yy"),"") | ... BV5: =IF(MONTH(BV6)<>MONTH(BU6),TEXT(BV6,"mmm yy"),"")
A6: Phase | B6: Task | C6: Epic | D6: Type | E6: Critical path | F6: Start offset (days) | G6: Length (days) | H6: Start | I6: End | J6: Weeks | K6: Status | L6: Stories / notes | N6: =$B$2 -> 46328 | O6: =N6+7 -> 46335 | P6: =O6+7 -> 46342 | Q6: =P6+7 -> 46349 | R6: =Q6+7 -> 46356 | S6: =R6+7 -> 46363 | T6: =S6+7 -> 46370 | U6: =T6+7 -> 46377 | V6: =U6+7 -> 46384 | ... BV6: =BU6+7 -> 46748
A7: Phase 0 | B7: Kickoff, contract and backlog review | D7: Task | E7: No | F7: 0 | G7: 4 | H7: =$B$2+F7 -> 46328 | I7: =H7+G7 -> 46332 | J7: =IF(D7="Milestone",0,ROUND((G7+3)/7,0)) -> 1 | K7: Not started | L7: Agree scope, team and ways of working
A8: Phase 0 | B8: Close open decisions (ADRs) | D8: Task | E8: No | F8: 0 | G8: 11 | H8: =$B$2+F8 -> 46328 | I8: =H8+G8 -> 46339 | J8: =IF(D8="Milestone",0,ROUND((G8+3)/7,0)) -> 2 | K8: Not started | L8: 12 business gaps + 9 technical decisions
A9: Phase 0 | B9: Paybill + Daraja production approval | D9: External | E9: Yes | F9: 0 | G9: 74 | H9: =$B$2+F9 -> 46328 | I9: =H9+G9 -> 46402 | J9: =IF(D9="Milestone",0,ROUND((G9+3)/7,0)) -> 11 | K9: Not started | L9: Safaricom lead time; apply on day one
A10: Phase 0 | B10: SMS sender ID registration | D10: External | E10: No | F10: 0 | G10: 32 | H10: =$B$2+F10 -> 46328 | I10: =H10+G10 -> 46360 | J10: =IF(D10="Milestone",0,ROUND((G10+3)/7,0)) -> 5 | K10: Not started | L10: Needed for receipts (LR-8.02)
A11: Phase 0 | B11: ODPC registration | D11: External | E11: No | F11: 0 | G11: 46 | H11: =$B$2+F11 -> 46328 | I11: =H11+G11 -> 46374 | J11: =IF(D11="Milestone",0,ROUND((G11+3)/7,0)) -> 7 | K11: Not started | L11: Data controller registration (SRS §13)
A12: Phase 0 | B12: Monorepo, CI and k3s dev server | C12: E13 | D12: Task | E12: No | F12: 7 | G12: 18 | H12: =$B$2+F12 -> 46335 | I12: =H12+G12 -> 46353 | J12: =IF(D12="Milestone",0,ROUND((G12+3)/7,0)) -> 3 | K12: Not started | L12: LR-13.01, 13.17
A13: Phase 0 | B13: OpenAPI contract v1 and ERD | C13: E13 | D13: Task | E13: No | F13: 7 | G13: 18 | H13: =$B$2+F13 -> 46335 | I13: =H13+G13 -> 46353 | J13: =IF(D13="Milestone",0,ROUND((G13+3)/7,0)) -> 3 | K13: Not started | L13: LR-13.18, 13.19; data model
A14: Phase 0 | B14: Wireframes for Phase 1 screens | D14: Task | E14: No | F14: 7 | G14: 25 | H14: =$B$2+F14 -> 46335 | I14: =H14+G14 -> 46360 | J14: =IF(D14="Milestone",0,ROUND((G14+3)/7,0)) -> 4 | K14: Not started | L14: Back office, tenant portal, caretaker view
A15: Phase 1 | B15: Users, roles, branch scope, audit | C15: E1 | D15: Task | E15: No | F15: 28 | G15: 18 | H15: =$B$2+F15 -> 46356 | I15: =H15+G15 -> 46374 | J15: =IF(D15="Milestone",0,ROUND((G15+3)/7,0)) -> 3 | K15: Not started | L15: LR-1.01 to 1.10
A16: Phase 1 | B16: Properties, units, landlords | C16: E2, E3 | D16: Task | E16: No | F16: 35 | G16: 46 | H16: =$B$2+F16 -> 46363 | I16: =H16+G16 -> 46409 | J16: =IF(D16="Milestone",0,ROUND((G16+3)/7,0)) -> 7 | K16: Not started | L16: LR-2.01 to 2.12, LR-3.01 to 3.06
A17: Phase 1 | B17: Tenants and tenancies | C17: E4 | D17: Task | E17: No | F17: 63 | G17: 32 | H17: =$B$2+F17 -> 46391 | I17: =H17+G17 -> 46423 | J17: =IF(D17="Milestone",0,ROUND((G17+3)/7,0)) -> 5 | K17: Not started | L17: LR-4.01 to 4.16 (P1)
A18: Phase 1 | B18: Invoicing, water billing, penalties | C18: E5 | D18: Task | E18: No | F18: 77 | G18: 25 | H18: =$B$2+F18 -> 46405 | I18: =H18+G18 -> 46430 | J18: =IF(D18="Milestone",0,ROUND((G18+3)/7,0)) -> 4 | K18: Not started | L18: LR-5.01 to 5.05, 5.18 to 5.20, 5.23
A19: Phase 1 | B19: M-Pesa C2B/STK, matching, allocation | C19: E5 | D19: Task | E19: Yes | F19: 70 | G19: 39 | H19: =$B$2+F19 -> 46398 | I19: =H19+G19 -> 46437 | J19: =IF(D19="Milestone",0,ROUND((G19+3)/7,0)) -> 6 | K19: Not started | L19: LR-5.06 to 5.17; queues LR-13.02 to 13.08
A20: Phase 1 | B20: SMS and email notifications | C20: E8 | D20: Task | E20: No | F20: 91 | G20: 18 | H20: =$B$2+F20 -> 46419 | I20: =H20+G20 -> 46437 | J20: =IF(D20="Milestone",0,ROUND((G20+3)/7,0)) -> 3 | K20: Not started | L20: LR-8.01 to 8.08
A21: Phase 1 | B21: Staging, production, DB replication | C21: E13 | D21: Task | E21: No | F21: 91 | G21: 25 | H21: =$B$2+F21 -> 46419 | I21: =H21+G21 -> 46444 | J21: =IF(D21="Milestone",0,ROUND((G21+3)/7,0)) -> 4 | K21: Not started | L21: LR-13.09 to 13.15
A22: Phase 1 | B22: Data migration and opening balances | C22: E13 | D22: Task | E22: No | F22: 105 | G22: 18 | H22: =$B$2+F22 -> 46433 | I22: =H22+G22 -> 46451 | J22: =IF(D22="Milestone",0,ROUND((G22+3)/7,0)) -> 3 | K22: Not started | L22: LR-13.16
A23: Phase 1 | B23: QA, performance, resilience, pen test | D23: Task | E23: Yes | F23: 112 | G23: 18 | H23: =$B$2+F23 -> 46440 | I23: =H23+G23 -> 46458 | J23: =IF(D23="Milestone",0,ROUND((G23+3)/7,0)) -> 3 | K23: Not started | L23: SRS §18.2 test cases; LR-13.20
A24: Phase 1 | B24: UAT and Phase 1 sign-off | D24: Task | E24: Yes | F24: 133 | G24: 11 | H24: =$B$2+F24 -> 46461 | I24: =H24+G24 -> 46472 | J24: =IF(D24="Milestone",0,ROUND((G24+3)/7,0)) -> 2 | K24: Not started | L24: Demo, UAT by agency staff, PM sign-off
A25: Phase 1 | B25: Phase 1 signed off | D25: Milestone | E25: Yes | F25: 144 | G25: 0 | H25: =$B$2+F25 -> 46472 | I25: =H25+G25 -> 46472 | J25: =IF(D25="Milestone",0,ROUND((G25+3)/7,0)) -> 0 | K25: Not started | L25: Gate
A26: Phase 1 | B26: Parallel run and staff training | D26: Task | E26: Yes | F26: 147 | G26: 25 | H26: =$B$2+F26 -> 46475 | I26: =H26+G26 -> 46500 | J26: =IF(D26="Milestone",0,ROUND((G26+3)/7,0)) -> 4 | K26: Not started | L26: One month against current records
A27: Phase 1 | B27: Rent collection go-live | D27: Milestone | E27: Yes | F27: 175 | G27: 0 | H27: =$B$2+F27 -> 46503 | I27: =H27+G27 -> 46503 | J27: =IF(D27="Milestone",0,ROUND((G27+3)/7,0)) -> 0 | K27: Not started | L27: Go-live
A28: Phase 2 | B28: Accounting, remittances, MRI | C28: E9 | D28: Task | E28: No | F28: 147 | G28: 32 | H28: =$B$2+F28 -> 46475 | I28: =H28+G28 -> 46507 | J28: =IF(D28="Milestone",0,ROUND((G28+3)/7,0)) -> 5 | K28: Not started | L28: LR-9.01 to 9.08, 9.11
A29: Phase 2 | B29: Maintenance, caretakers, vendors | C29: E7 | D29: Task | E29: No | F29: 161 | G29: 32 | H29: =$B$2+F29 -> 46489 | I29: =H29+G29 -> 46521 | J29: =IF(D29="Milestone",0,ROUND((G29+3)/7,0)) -> 5 | K29: Not started | L29: LR-7.01 to 7.06, 7.10
A30: Phase 2 | B30: Landlord and tenant portals | C30: E3, E4 | D30: Task | E30: No | F30: 168 | G30: 25 | H30: =$B$2+F30 -> 46496 | I30: =H30+G30 -> 46521 | J30: =IF(D30="Milestone",0,ROUND((G30+3)/7,0)) -> 4 | K30: Not started | L30: Portal dashboards and statements
A31: Phase 2 | B31: Reports and dashboards | C31: E11 | D31: Task | E31: No | F31: 175 | G31: 25 | H31: =$B$2+F31 -> 46503 | I31: =H31+G31 -> 46528 | J31: =IF(D31="Milestone",0,ROUND((G31+3)/7,0)) -> 4 | K31: Not started | L31: LR-11.01 to 11.20 (P1)
A32: Phase 2 | B32: Compliance and data protection | C32: E12 | D32: Task | E32: No | F32: 182 | G32: 18 | H32: =$B$2+F32 -> 46510 | I32: =H32+G32 -> 46528 | J32: =IF(D32="Milestone",0,ROUND((G32+3)/7,0)) -> 3 | K32: Not started | L32: LR-12.01, 12.03 to 12.05, 12.07, 12.09, 12.10
A33: Phase 2 | B33: QA, UAT and sign-off | D33: Task | E33: No | F33: 203 | G33: 11 | H33: =$B$2+F33 -> 46531 | I33: =H33+G33 -> 46542 | J33: =IF(D33="Milestone",0,ROUND((G33+3)/7,0)) -> 2 | K33: Not started | L33: Remittance totals match the ledger
A34: Phase 2 | B34: Phase 2 signed off | D34: Milestone | E34: No | F34: 214 | G34: 0 | H34: =$B$2+F34 -> 46542 | I34: =H34+G34 -> 46542 | J34: =IF(D34="Milestone",0,ROUND((G34+3)/7,0)) -> 0 | K34: Not started | L34: Gate
A35: Phase 3 | B35: Projects, plots, sales pipeline, plans | C35: E6 | D35: Task | E35: No | F35: 217 | G35: 32 | H35: =$B$2+F35 -> 46545 | I35: =H35+G35 -> 46577 | J35: =IF(D35="Milestone",0,ROUND((G35+3)/7,0)) -> 5 | K35: Not started | L35: LR-6.01 to 6.09
A36: Phase 3 | B36: Due diligence, transfers, buyer portal | C36: E6 | D36: Task | E36: No | F36: 238 | G36: 18 | H36: =$B$2+F36 -> 46566 | I36: =H36+G36 -> 46584 | J36: =IF(D36="Milestone",0,ROUND((G36+3)/7,0)) -> 3 | K36: Not started | L36: LR-6.11 to 6.13
A37: Phase 3 | B37: QA, UAT and sign-off | D37: Task | E37: No | F37: 259 | G37: 11 | H37: =$B$2+F37 -> 46587 | I37: =H37+G37 -> 46598 | J37: =IF(D37="Milestone",0,ROUND((G37+3)/7,0)) -> 2 | K37: Not started | L37: 12-month plan reminders; title tracking
A38: Phase 3 | B38: Phase 3 signed off | D38: Milestone | E38: No | F38: 270 | G38: 0 | H38: =$B$2+F38 -> 46598 | I38: =H38+G38 -> 46598 | J38: =IF(D38="Milestone",0,ROUND((G38+3)/7,0)) -> 0 | K38: Not started | L38: Gate
A39: Phase 4 | B39: Public website and SEO listings | C39: E10 | D39: Task | E39: No | F39: 273 | G39: 25 | H39: =$B$2+F39 -> 46601 | I39: =H39+G39 -> 46626 | J39: =IF(D39="Milestone",0,ROUND((G39+3)/7,0)) -> 4 | K39: Not started | L39: LR-10.01 to 10.04
A40: Phase 4 | B40: Leads, viewings, match engine | C40: E10 | D40: Task | E40: No | F40: 287 | G40: 18 | H40: =$B$2+F40 -> 46615 | I40: =H40+G40 -> 46633 | J40: =IF(D40="Milestone",0,ROUND((G40+3)/7,0)) -> 3 | K40: Not started | L40: LR-10.06 to 10.09
A41: Phase 4 | B41: Extras: WhatsApp, eTIMS, Swahili, VAT | D41: Task | E41: No | F41: 294 | G41: 25 | H41: =$B$2+F41 -> 46622 | I41: =H41+G41 -> 46647 | J41: =IF(D41="Milestone",0,ROUND((G41+3)/7,0)) -> 4 | K41: Not started | L41: 32 P2/P3 stories across epics
...

Sheet Phases
A1: Phases at a glance
A2: Start and end come from the Schedule tab (external lead times excluded). P1 story counts come from the Story Counts tab.
A4: Phase | B4: Name | C4: Start | D4: End | E4: Weeks | F4: Epics | G4: P1 stories | H4: Exit gate
A5: Phase 0 | B5: Mobilise and set up | C5: =_xlfn.MINIFS(Schedule!$H$7:$H$44,Schedule!$A$7:$A$44,A5,Schedule!$D$7:$D$44,"<>External") -> 46328 | D5: =_xlfn.MAXIFS(Schedule!$I$7:$I$44,Schedule!$A$7:$A$44,A5,Schedule!$D$7:$D$44,"<>External") -> 46360 | E5: =ROUND((D5-C5+3)/7,0) -> 5 | F5: Decisions, E13 setup | G5: =SUMIFS('Story Counts'!$C$5:$C$17,'Story Counts'!$G$5:$G$17,A5) -> 0 | H5: Contract signed, ADRs agreed, dev server and CI running
A6: Phase 1 | B6: Rent collection | C6: =_xlfn.MINIFS(Schedule!$H$7:$H$44,Schedule!$A$7:$A$44,A6,Schedule!$D$7:$D$44,"<>External") -> 46356 | D6: =_xlfn.MAXIFS(Schedule!$I$7:$I$44,Schedule!$A$7:$A$44,A6,Schedule!$D$7:$D$44,"<>External") -> 46503 | E6: =ROUND((D6-C6+3)/7,0) -> 21 | F6: E1, E2, E3, E4, E5, E8, E13 | G6: =SUMIFS('Story Counts'!$C$5:$C$17,'Story Counts'!$G$5:$G$17,A6) -> 88 | H6: UAT sign-off 26 Mar, parallel run, go-live 26 Apr
A7: Phase 2 | B7: Accounts, maintenance, reports | C7: =_xlfn.MINIFS(Schedule!$H$7:$H$44,Schedule!$A$7:$A$44,A7,Schedule!$D$7:$D$44,"<>External") -> 46475 | D7: =_xlfn.MAXIFS(Schedule!$I$7:$I$44,Schedule!$A$7:$A$44,A7,Schedule!$D$7:$D$44,"<>External") -> 46542 | E7: =ROUND((D7-C7+3)/7,0) -> 10 | F7: E7, E9, E11, E12 | G7: =SUMIFS('Story Counts'!$C$5:$C$17,'Story Counts'!$G$5:$G$17,A7) -> 39 | H7: Landlord remittances and MRI verified against the ledger
A8: Phase 3 | B8: Land sales | C8: =_xlfn.MINIFS(Schedule!$H$7:$H$44,Schedule!$A$7:$A$44,A8,Schedule!$D$7:$D$44,"<>External") -> 46545 | D8: =_xlfn.MAXIFS(Schedule!$I$7:$I$44,Schedule!$A$7:$A$44,A8,Schedule!$D$7:$D$44,"<>External") -> 46598 | E8: =ROUND((D8-C8+3)/7,0) -> 8 | F8: E6 | G8: =SUMIFS('Story Counts'!$C$5:$C$17,'Story Counts'!$G$5:$G$17,A8) -> 12 | H8: 12-month buyer plan and transfer checklist pass UAT
A9: Phase 4 | B9: Website, CRM and extras | C9: =_xlfn.MINIFS(Schedule!$H$7:$H$44,Schedule!$A$7:$A$44,A9,Schedule!$D$7:$D$44,"<>External") -> 46601 | D9: =_xlfn.MAXIFS(Schedule!$I$7:$I$44,Schedule!$A$7:$A$44,A9,Schedule!$D$7:$D$44,"<>External") -> 46654 | E9: =ROUND((D9-C9+3)/7,0) -> 8 | F9: E10 + P2/P3 extras | G9: =SUMIFS('Story Counts'!$C$5:$C$17,'Story Counts'!$G$5:$G$17,A9) -> 5 | H9: Final sign-off and handover
A10: Extras | B10: P2 and P3 stories (scheduled in the Phase 4 extras window) | G10: ='Story Counts'!D18+'Story Counts'!E18 -> 32
A11: Total | G11: =SUM(G5:G10) -> 176
A13: Key dates
A14: Phase 1 sign-off | B14: =INDEX(Schedule!$H$7:$H$44,MATCH("Phase 1 signed off",Schedule!$B$7:$B$44,0)) -> 46472
A15: Rent collection go-live | B15: =INDEX(Schedule!$H$7:$H$44,MATCH("Rent collection go-live",Schedule!$B$7:$B$44,0)) -> 46503
A16: Final project sign-off | B16: =INDEX(Schedule!$H$7:$H$44,MATCH("Project sign-off",Schedule!$B$7:$B$44,0)) -> 46654
A17: Weeks from kickoff to go-live | B17: =ROUND((B15-Schedule!$B$2)/7,0) -> 25
A18: Weeks from kickoff to final sign-off | B18: =ROUND((B16-Schedule!$B$2+3)/7,0) -> 47
A19: Daraja approval slack before Phase 1 testing (weeks) | B19: =ROUND((INDEX(Schedule!$H$7:$H$44,MATCH("QA, performance, resilience, pen test",Schedule!$B$7:$B$44,0))-INDEX(Schedule!$I$7:$I$44,MATCH("Paybill + Daraja production approval",Schedule!$B$7:$B$44,0)))/7,0) -> 5

Sheet Story Counts
A1: User stories by epic and priority
A2: Source: Legacy Real Estate System — User Stories backlog (18 Oct 2026). P1 = first go-live, P2 = later phase, P3 = optional.
A4: Epic | B4: Name | C4: P1 | D4: P2 | E4: P3 | F4: Total | G4: Phase
A5: E1 | B5: Access, roles and audit | C5: 10 | D5: 0 | E5: 0 | F5: =SUM(C5:E5) -> 10 | G5: Phase 1
A6: E2 | B6: Property and unit management | C6: 11 | D6: 1 | E6: 0 | F6: =SUM(C6:E6) -> 12 | G6: Phase 1
A7: E3 | B7: Landlord management | C7: 6 | D7: 1 | E7: 0 | F7: =SUM(C7:E7) -> 7 | G7: Phase 1
A8: E4 | B8: Tenant management and tenancies | C8: 13 | D8: 3 | E8: 0 | F8: =SUM(C8:E8) -> 16 | G8: Phase 1
A9: E5 | B9: Rent billing, payments and arrears | C9: 20 | D9: 3 | E9: 0 | F9: =SUM(C9:E9) -> 23 | G9: Phase 1
A10: E6 | B10: Land sales | C10: 12 | D10: 2 | E10: 1 | F10: =SUM(C10:E10) -> 15 | G10: Phase 3
A11: E7 | B11: Maintenance, caretakers and inspections | C11: 7 | D11: 3 | E11: 0 | F11: =SUM(C11:E11) -> 10 | G11: Phase 2
A12: E8 | B12: Communications | C12: 8 | D12: 2 | E12: 0 | F12: =SUM(C12:E12) -> 10 | G12: Phase 1
A13: E9 | B13: Accounting, remittances and tax | C13: 9 | D13: 4 | E13: 0 | F13: =SUM(C13:E13) -> 13 | G13: Phase 2
A14: E10 | B14: Public website and CRM | C14: 5 | D14: 4 | E14: 1 | F14: =SUM(C14:E14) -> 10 | G14: Phase 4
A15: E11 | B15: Reports and dashboards | C15: 16 | D15: 4 | E15: 0 | F15: =SUM(C15:E15) -> 20 | G15: Phase 2
A16: E12 | B16: Compliance and data protection | C16: 7 | D16: 3 | E16: 0 | F16: =SUM(C16:E16) -> 10 | G16: Phase 2
A17: E13 | B17: Platform, infrastructure, non-functional | C17: 20 | D17: 0 | E17: 0 | F17: =SUM(C17:E17) -> 20 | G17: Phase 1
A18: Total | C18: =SUM(C5:C17) -> 144 | D18: =SUM(D5:D17) -> 30 | E18: =SUM(E5:E17) -> 2 | F18: =SUM(F5:F17) -> 176
A20: Largest epic | B20: =INDEX(B5:B17,MATCH(MAX(F5:F17),F5:F17,0)) -> Rent billing, payments and arrears
A21: Share of P1 stories in Phase 1 | B21: =SUMIFS(C5:C17,G5:G17,"Phase 1")/C18 -> 0.61111111

Sheet Analysis
A1: Analysis, critical path, assumptions and risks
A3: Critical path
A4: 1 | B4: Paybill and Daraja production approval
A5: 2 | B5: M-Pesa matching and allocation
A6: 3 | B6: Phase 1 QA, performance and resilience tests
A7: 4 | B7: UAT and sign-off
A8: 5 | B8: One-month parallel run
A9: 6 | B9: Rent collection go-live
A11: Findings
A12: • | B12: Payments are the heaviest epic: Epic 5 has 23 stories and touches billing, accounting, notifications and the queues.
A13: • | B13: Platform work comes first: queues, idempotent callbacks, replication and Kubernetes (Epic 13, 20 stories) must be ready before payments can be tested.
A14: • | B14: Three outside lead times start on day one: Paybill/Daraja approval, SMS sender ID and ODPC registration (SRS §18.3).
A15: • | B15: 21 decisions are still open (12 business gaps + 9 technical decisions); Phase 0 sets aside two weeks to close them.
A16: • | B16: The website comes last because the SRS ranks it below rent collection; Epic 10 can move into Phase 2 with about 4 more weeks of effort.
A18: Planning assumptions
A19: • | B19: Kickoff Monday 2 November 2026 (editable on the Schedule tab).
A20: • | B20: Team: one lead full-stack developer, one frontend developer, QA and a project manager. A single developer roughly doubles the build durations.
A21: • | B21: Light work from 21 December to 1 January.
A22: • | B22: Each phase ends with a demo, UAT by agency staff and PM sign-off (SRS §18).
A23: • | B23: Go-live follows the SRS: data migration, one-month parallel run, staff training, switch-over.
A24: • | B24: Warranty: 3 months of bug fixes after final sign-off.
A26: Schedule risks
B27: Risk | C27: Impact | D27: Mitigation
B28: Daraja approval takes longer than 11 weeks | C28: Go-live slips | D28: Apply on day one; build against the sandbox; about 5 weeks of slack
B29: Open decisions not closed in Phase 0 | C29: Schema rework mid-build | D29: Two-week decision window; ADRs signed off before modules start
B30: Opening balances do not reconcile | C30: Wrong arrears from day one | D30: Import validation per row; one-month parallel run
B31: Team smaller than assumed | C31: Build bars roughly double | D31: Re-estimate in Phase 0; protect the rent-collection scope
B32: December holiday slowdown | C32: Phase 1 build compressed | D32: Shaded on the plan; avoid gates in the holiday weeks
